Workbook

Sheet A5
A1: PROJET: TEMARA AVENUE ETAT DE POSE
A2: =RECAP!A2 -> DU 01/02/26 AU 16/02/26
D5: A5 | AJ5: RECAP DE POSE
D6: 1ér ETAGE | H6: 2e ETAGE | L6: 3e ETAGE | P6: 4e ETAGE | T6: 5e ETAGE | X6: 6e ETAGE | AB6: COMMUNS
B7: ARTICLES | C7: DECOMPOSITION | D7: APPART 1 | E7: APPART 2 | F7: APPART 3 | G7: APPART 4 | H7: APPART 5 | I7: APPART 6 | J7: APPART 7 | K7: APPART 8 | L7: APPART 9 | M7: APPART 10 | N7: APPART 11 | O7: APPART 12 | P7: APPART 13 | Q7: APPART 14 | R7: APPART 15 | S7: APPART 16 | T7: APPART 17 | U7: APPART 18 | V7: APPART 19 | W7: APPART 20 | X7: APPART 21 | Y7: APPART 22 | Z7: APPART 23 | AA7: APPART 24 | AB7: 6éme étage | AC7: 5éme étage | AD7: 4éme étage | AE7: 3éme étage | AF7: 2éme étage | AG7: 1ér étage | AH7: MEZZ | AI7: RDC
A8: POSEUR ZOUHAIR | B8: PORTES D'ENTRÉE | C8: Cadre + Panneau | AJ8: =SUM(D8:AI8) -> 0
C9: Chambranle + Habillage | AJ9: =SUM(D9:AI9) -> 0
C10: Imposte | AJ10: =SUM(D10:AI10) -> 0
C11: Butoirs, Judas, Poignée et serrures , Canon | AJ11: =SUM(D11:AI11) -> 0
B12: PORTES INTÉRIEURES | C12: Cadre + Panneau | AJ12: =SUM(D12:AI12) -> 0
C13: Chambranle + Habillage | AJ13: =SUM(D13:AI13) -> 0
C14: Imposte | AJ14: =SUM(D14:AI14) -> 0
C15: Butoirs, Poignée et serrures, Canon & Condamnation | AJ15: =SUM(D15:AI15) -> 0
B16: PORTES ESCALIERS / SECOURS | C16: Cadre + Panneau | AB16: 2 | AC16: 1 | AD16: 1 | AE16: 1 | AF16: 1 | AG16: 2 | AI16: 1 | AJ16: =SUM(D16:AI16) -> 9
C17: Chambranle + Habillage | AB17: 2 | AC17: 1 | AD17: 1 | AE17: 1 | AF17: 1 | AG17: 2 | AH17: 0 | AI17: 1 | AJ17: =SUM(D17:AI17) -> 9
C18: Imposte | AB18: 2 | AC18: 1 | AD18: 1 | AE18: 1 | AF18: 1 | AG18: 2 | AH18: 0 | AI18: 1 | AJ18: =SUM(D18:AI18) -> 9
C19: Ferme porte, Poignée et serrures, Barre anti panique | AB19: 2 | AC19: 1 | AD19: 1 | AE19: 1 | AF19: 1 | AG19: 2 | AH19: 0 | AI19: 1 | AJ19: =SUM(D19:AI19) -> 9
A20: POSEUR ZEMOURI | B20: PLACARDS | C20: Amg Caisson ( quantité en ouvrants) | AJ20: =SUM(D20:AI20) -> 0
C21: Etageres | AJ21: =SUM(D21:AI21) -> 0
C22: Ouvrants | AJ22: =SUM(D22:AI22) -> 0
C23: Chambranle | AJ23: =SUM(D23:AI23) -> 0
C24: Boc titoir | AJ24: =SUM(D24:AI24) -> 0
C25: Tringles & Accessoires | AJ25: =SUM(D25:AI25) -> 0
B26: DRESSINGS | C26: Amg Caisson+ Etageres | AJ26: =SUM(D26:AI26) -> 0
C27: Chambranle | AJ27: =SUM(D27:AI27) -> 0
C28: Boc titoir | AJ28: =SUM(D28:AI28) -> 0
C29: Tringles & Accessoires | AJ29: =SUM(D29:AI29) -> 0
B30: PLACARD TECHNIQUE | C30: Cadre + Panneau | AB30: 2 | AC30: 2 | AD30: 2 | AE30: 2 | AF30: 2 | AG30: 2 | AJ30: =SUM(D30:AI30) -> 12
C31: Poignées et accessoires | AJ31: =SUM(D31:AI31) -> 0
A32: HICHAM | B32: CUISINE | C32: Caisson bas | D32: 274 | E32: 245 | F32: 290 | G32: 245 | H32: 274 | I32: 245 | J32: 290 | K32: 245 | L32: 274 | M32: 245 | N32: 290 | O32: 245 | P32: 274 | Q32: 245 | R32: 290 | S32: 245 | T32: 274 | U32: 245 | V32: 290 | W32: 245 | X32: 225 | Y32: 235 | Z32: 225 | AJ32: =SUM(D32:AI32) -> 5955
C33: Caisson haut | D33: 274 | E33: 245 | F33: 290 | G33: 245 | H33: 274 | I33: 245 | J33: 290 | K33: 245 | L33: 274 | M33: 245 | N33: 290 | O33: 245 | P33: 274 | Q33: 245 | R33: 290 | S33: 245 | T33: 274 | U33: 245 | V33: 290 | W33: 245 | X33: 225 | Y33: 235 | Z33: 225 | AJ33: =SUM(D33:AI33) -> 5955
C34: Façades & faces tiroir | D34: 548 | E34: 490 | F34: 580 | G34: 490 | H34: 548 | I34: 490 | J34: 580 | K34: 490 | L34: 548 | M34: 490 | N34: 580 | O34: 490 | P34: 548 | Q34: 490 | R34: 580 | S34: 490 | T34: 548 | U34: 490 | V34: 580 | W34: 490 | X34: 450 | Y34: 470 | Z34: 450 | AJ34: =SUM(D34:AI34) -> 11910
C35: Poignées | AJ35: =SUM(D35:AI35) -> 0
A36: AYOUB | C36: PDT | Z36: 225 | AJ36: =SUM(D36:AI36) -> 225
C37: Decoupe | Z37: 1 | AJ37: =SUM(D37:AI37) -> 1
C38: Socle de sol | Z38: 1 | AJ38: =SUM(D38:AI38) -> 1
C39: Crédence | Z39: 1 | AJ39: =SUM(D39:AI39) -> 1
C40: Plinthe sur PDT | D40: 1 | E40: 1 | F40: 1 | G40: 1 | H40: 1 | I40: 1 | J40: 1 | K40: 1 | L40: 1 | M40: 1 | N40: 1 | O40: 1 | P40: 1 | Q40: 1 | R40: 1 | S40: 1 | T40: 1 | U40: 1 | V40: 1 | W40: 1 | X40: 1 | Y40: 1 | Z40: 1 | AJ40: =SUM(D40:AI40) -> 23

Sheet A4
A1: PROJET: TEMARA AVENUE ETAT DE POSE
A2: =RECAP!A2 -> DU 01/02/26 AU 16/02/26
D5: A4 | AF5: RECAP DE POSE
D6: RDC | F6: 1ér ETAGE | I6: 2e ETAGE | L6: 3e ETAGE | O6: 4e ETAGE | R6: 5e ETAGE | U6: 6e ETAGE | X6: COMMUNS
B7: ARTICLES | C7: DECOMPOSITION | D7: APPART 1 | E7: APPART 2 | F7: APPART 3 | G7: APPART 4 | H7: APPART 5 | I7: APPART 6 | J7: APPART 7 | K7: APPART 8 | L7: APPART 9 | M7: APPART 10 | N7: APPART 11 | O7: APPART 12 | P7: APPART 13 | Q7: APPART 14 | R7: APPART 15 | S7: APPART 16 | T7: APPART 17 | U7: APPART 18 | V7: APPART 19 | W7: APPART 20 | X7: 6éme étage | Y7: 5éme étage | Z7: 4éme étage | AA7: 3éme étage | AB7: 2éme étage | AC7: 1ér étage | AD7: MEZZ | AE7: RDC
A8: POSEUR ZOUHAIR | B8: PORTES D'ENTRÉE | C8: Cadre + Panneau | AF8: =SUM(D8:AE8) -> 0
C9: Chambranle + Habillage | AF9: =SUM(D9:AE9) -> 0
C10: Imposte | AF10: =SUM(D10:AE10) -> 0
C11: Butoirs, Judas, Poignée et serrures , Canon | AF11: =SUM(D11:AE11) -> 0
B12: PORTES INTÉRIEURES | C12: Cadre + Panneau | D12: 4 | E12: 4 | F12: 3 | AF12: =SUM(D12:AE12) -> 11
C13: Chambranle + Habillage | AF13: =SUM(D13:AE13) -> 0
C14: Imposte | AF14: =SUM(D14:AE14) -> 0
C15: Butoirs, Poignée et serrures, Canon & Condamnation | AF15: =SUM(D15:AE15) -> 0
B16: PORTES ESCALIERS / SECOURS | C16: Cadre + Panneau | X16: 2 | Y16: 2 | Z16: 2 | AA16: 2 | AB16: 2 | AC16: 2 | AE16: 1 | AF16: =SUM(D16:AE16) -> 13
C17: Chambranle + Habillage | X17: 2 | Y17: 2 | Z17: 2 | AA17: 2 | AB17: 2 | AC17: 2 | AE17: 1 | AF17: =SUM(D17:AE17) -> 13
C18: Imposte | X18: 2 | Y18: 2 | Z18: 2 | AA18: 2 | AB18: 2 | AC18: 2 | AE18: 1 | AF18: =SUM(D18:AE18) -> 13
C19: Ferme porte, Poignée et serrures, Barre anti panique | X19: 2 | Y19: 2 | Z19: 2 | AA19: 2 | AB19: 2 | AC19: 2 | AE19: 1 | AF19: =SUM(D19:AE19) -> 13
A20: POSEUR ZEMOURI | B20: PLACARDS | C20: Amg Caisson ( quantité en ouvrants) | AF20: =SUM(D20:AE20) -> 0
C21: Etageres | AF21: =SUM(D21:AE21) -> 0
C22: Ouvrants | AF22: =SUM(D22:AE22) -> 0
C23: Chambranle | AF23: =SUM(D23:AE23) -> 0
C24: Boc titoir | AF24: =SUM(D24:AE24) -> 0
C25: Tringles & Accessoires | AF25: =SUM(D25:AE25) -> 0
B26: DRESSINGS | C26: Amg Caisson+ Etageres | AF26: =SUM(D26:AE26) -> 0
C27: Chambranle | AF27: =SUM(D27:AE27) -> 0
C28: Boc titoir | AF28: =SUM(D28:AE28) -> 0
C29: Tringles & Accessoires | AF29: =SUM(D29:AE29) -> 0
B30: PLACARD TECHNIQUE | C30: Cadre + Panneau | X30: 2 | Y30: 2 | Z30: 2 | AA30: 2 | AB30: 2 | AC30: 2 | AF30: =SUM(D30:AE30) -> 12
C31: Poignées et accessoires | AF31: =SUM(D31:AE31) -> 0
A32: HICHAM | B32: CUISINE | C32: Caisson bas | F32: 265 | G32: 244 | H32: 225 | I32: 264 | J32: 234 | K32: 225 | L32: 265 | M32: 234 | N32: 225 | O32: 264 | P32: 235 | Q32: 225 | R32: 266 | S32: 235 | T32: 225 | U32: 225 | V32: 226 | AF32: =SUM(D32:AE32) -> 4082
C33: Caisson haut | F33: 265 | G33: 244 | H33: 225 | I33: 264 | J33: 234 | K33: 225 | L33: 265 | M33: 234 | N33: 225 | O33: 264 | P33: 235 | Q33: 225 | R33: 266 | S33: 235 | T33: 225 | U33: 225 | V33: 226 | AF33: =SUM(D33:AE33) -> 4082
C34: Façades & faces tiroir | F34: 530 | G34: 488 | H34: 450 | I34: 528 | J34: 468 | K34: 450 | L34: 530 | M34: 468 | N34: 450 | O34: 528 | P34: 470 | Q34: 450 | R34: 532 | S34: 470 | T34: 450 | U34: 450 | V34: 452 | AF34: =SUM(D34:AE34) -> 8164
C35: Poignées | AF35: =SUM(D35:AE35) -> 0
A36: AYOUB | C36: PDT | F36: 265 | G36: 244 | H36: 225 | I36: 264 | J36: 234 | K36: 225 | L36: 265 | M36: 234 | N36: 225 | O36: 264 | P36: 235 | Q36: 225 | R36: 266 | S36: 235 | T36: 225 | U36: 225 | V36: 226 | AF36: =SUM(D36:AE36) -> 4082
C37: Decoupe | AF37: =SUM(D37:AE37) -> 0
C38: Socle de sol | H38: 1 | K38: 1 | N38: 1 | Q38: 1 | T38: 1 | AF38: =SUM(D38:AE38) -> 5
C39: Crédence | F39: 1 | G39: 1 | H39: 1 | I39: 1 | J39: 1 | K39: 1 | L39: 1 | M39: 1 | N39: 1 | O39: 1 | P39: 1 | Q39: 1 | R39: 1 | S39: 1 | T39: 1 | U39: 1 | V39: 1 | AF39: =SUM(D39:AE39) -> 17
C40: Plinthe sur PDT | AF40: =SUM(D40:AE40) -> 0

Sheet A3
A1: PROJET: TEMARA AVENUE ETAT DE POSE
A2: =RECAP!A2 -> DU 01/02/26 AU 16/02/26
D5: A3 | AS5: RECAP DE POSE
D6: RDC | G6: 1ér ETAGE | L6: 2e ETAGE | Q6: 3e ETAGE | V6: 4e ETAGE | AA6: 5e ETAGE | AF6: 6e ETAGE | AK6: COMMUNS
B7: ARTICLES | C7: DECOMPOSITION | D7: APPART 1 | E7: APPART 2 | F7: APPART 3 | G7: APPART 4 | H7: APPART 5 | I7: APPART 6 | J7: APPART 7 | K7: APPART 8 | L7: APPART 9 | M7: APPART 10 | N7: APPART 11 | O7: APPART 12 | P7: APPART 13 | Q7: APPART 14 | R7: APPART 15 | S7: APPART 16 | T7: APPART 17 | U7: APPART 18 | V7: APPART 19 | W7: APPART 20 | X7: APPART 21 | Y7: APPART 22 | Z7: APPART 23 | AA7: APPART 24 | AB7: APPART 25 | AC7: APPART 26 | AD7: APPART 27 | AE7: APPART 28 | AF7: APPART 29 | AG7: APPART 30 | AH7: APPART 31 | AI7: APPART 32 | AJ7: APPART 33 | AK7: 6éme étage | AL7: 5éme étage | AM7: 4éme étage | AN7: 3éme étage | AO7: 2éme étage | AP7: 1ér étage | AQ7: MEZZ | AR7: RDC
A8: POSEUR ZOUHAIR | B8: PORTES D'ENTRÉE | C8: Cadre + Panneau | D8: 1 | G8: 1 | H8: 1 | I8: 1 | J8: 1 | K8: 1 | L8: 1 | M8: 1 | N8: 1 | O8: 1 | P8: 1 | Q8: 1 | R8: 1 | S8: 1 | T8: 1 | U8: 1 | V8: 1 | W8: 1 | X8: 1 | Y8: 1 | Z8: 1 | AA8: 1 | AB8: 1 | AC8: 1 | AD8: 1 | AE8: 1 | AF8: 1 | AG8: 1 | AH8: 1 | AI8: 1 | AJ8: 1 | AS8: =SUM(D8:AR8) -> 31
C9: Chambranle + Habillage | G9: 1 | H9: 1 | I9: 1 | J9: 1 | K9: 1 | L9: 1 | M9: 1 | N9: 1 | O9: 1 | P9: 1 | Q9: 1 | R9: 1 | S9: 1 | T9: 1 | U9: 1 | V9: 1 | W9: 1 | X9: 1 | Y9: 1 | Z9: 1 | AA9: 1 | AB9: 1 | AC9: 1 | AD9: 1 | AE9: 1 | AF9: 1 | AG9: 1 | AH9: 1 | AI9: 1 | AJ9: 1 | AS9: =SUM(D9:AR9) -> 30
C10: Imposte | G10: 1 | H10: 1 | I10: 1 | J10: 1 | K10: 1 | L10: 1 | M10: 1 | N10: 1 | O10: 1 | P10: 1 | Q10: 1 | R10: 1 | S10: 1 | T10: 1 | U10: 1 | V10: 1 | W10: 1 | X10: 1 | Y10: 1 | Z10: 1 | AA10: 1 | AB10: 1 | AC10: 1 | AD10: 1 | AE10: 1 | AF10: 1 | AG10: 1 | AH10: 1 | AI10: 1 | AJ10: 1 | AS10: =SUM(D10:AR10) -> 30
C11: Butoirs, Judas, Poignée et serrures , Canon | AS11: =SUM(D11:AR11) -> 0
B12: PORTES INTÉRIEURES | C12: Cadre + Panneau | D12: 1 | E12: 5 | F12: 4 | G12: 8 | H12: 7 | I12: 4 | J12: 7 | K12: 5 | L12: 8 | M12: 7 | N12: 4 | O12: 7 | P12: 5 | Q12: 8 | R12: 7 | S12: 4 | T12: 7 | U12: 5 | V12: 8 | W12: 7 | X12: 4 | Y12: 7 | Z12: 5 | AA12: 8 | AB12: 7 | AC12: 4 | AD12: 7 | AE12: 5 | AF12: 7 | AG12: 7 | AH12: 4 | AI12: 7 | AJ12: 5 | AS12: =SUM(D12:AR12) -> 195
C13: Chambranle + Habillage | G13: 8 | H13: 7 | I13: 4 | J13: 7 | K13: 5 | L13: 8 | M13: 7 | N13: 4 | O13: 7 | P13: 5 | Q13: 8 | R13: 7 | S13: 4 | T13: 7 | U13: 5 | V13: 8 | W13: 7 | X13: 4 | Y13: 7 | Z13: 5 | AA13: 8 | AB13: 7 | AC13: 4 | AD13: 7 | AE13: 5 | AF13: 7 | AG13: 7 | AH13: 4 | AI13: 7 | AJ13: 5 | AS13: =SUM(D13:AR13) -> 185
C14: Imposte | G14: 8 | H14: 7 | I14: 4 | J14: 7 | K14: 5 | L14: 8 | M14: 7 | N14: 4 | O14: 7 | P14: 5 | Q14: 8 | R14: 7 | S14: 4 | T14: 7 | U14: 5 | V14: 8 | W14: 7 | X14: 4 | Y14: 7 | Z14: 5 | AA14: 8 | AB14: 7 | AC14: 4 | AD14: 7 | AE14: 5 | AF14: 7 | AG14: 7 | AH14: 4 | AI14: 7 | AJ14: 5 | AS14: =SUM(D14:AR14) -> 185
C15: Butoirs, Poignée et serrures, Canon & Condamnation | AS15: =SUM(D15:AR15) -> 0
B16: PORTES ESCALIERS / SECOURS | C16: Cadre + Panneau | AK16: 2 | AL16: 2 | AM16: 2 | AN16: 2 | AO16: 2 | AP16: 1 | AR16: 1 | AS16: =SUM(D16:AR16) -> 12
C17: Chambranle + Habillage | AS17: =SUM(D17:AR17) -> 0
C18: Imposte | AK18: 2 | AL18: 2 | AM18: 2 | AN18: 2 | AO18: 2 | AP18: 1 | AR18: 1 | AS18: =SUM(D18:AR18) -> 12
C19: Ferme porte, Poignée et serrures, Barre anti panique | AK19: 2 | AL19: 2 | AM19: 2 | AN19: 2 | AO19: 2 | AP19: 1 | AR19: 1 | AS19: =SUM(D19:AR19) -> 12
A20: POSEUR ZEMOURI | B20: PLACARDS | C20: Amg Caisson ( quantité en ouvrants) | G20: 9 | H20: 7 | I20: 5 | J20: 9 | K20: 6 | L20: 9 | M20: 7 | N20: 5 | O20: 9 | P20: 6 | Q20: 9 | R20: 7 | S20: 5 | T20: 9 | U20: 6 | V20: 9 | W20: 7 | X20: 5 | Y20: 9 | Z20: 6 | AA20: 9 | AB20: 7 | AC20: 5 | AD20: 9 | AE20: 6 | AF20: 9 | AG20: 7 | AH20: 5 | AI20: 9 | AJ20: 6 | AS20: =SUM(D20:AR20) -> 216
C21: Etageres | G21: 18 | H21: 20 | I21: 12 | J21: 18 | K21: 12 | L21: 18 | M21: 20 | N21: 12 | O21: 18 | P21: 12 | Q21: 18 | R21: 20 | S21: 12 | T21: 18 | U21: 12 | V21: 18 | W21: 20 | X21: 12 | Y21: 18 | Z21: 12 | AA21: 18 | AB21: 20 | AC21: 12 | AD21: 18 | AE21: 12 | AF21: 18 | AG21: 20 | AH21: 12 | AI21: 18 | AJ21: 12 | AS21: =SUM(D21:AR21) -> 480
C22: Ouvrants | G22: 9 | H22: 7 | I22: 5 | J22: 9 | K22: 6 | L22: 9 | M22: 7 | N22: 5 | O22: 9 | P22: 6 | Q22: 9 | R22: 7 | S22: 5 | T22: 9 | U22: 6 | V22: 9 | W22: 7 | X22: 5 | Y22: 9 | Z22: 6 | AA22: 9 | AB22: 7 | AC22: 5 | AD22: 9 | AE22: 6 | AF22: 9 | AG22: 7 | AH22: 5 | AI22: 9 | AJ22: 6 | AS22: =SUM(D22:AR22) -> 216
C23: Chambranle | G23: 9 | H23: 7 | I23: 5 | J23: 9 | K23: 6 | L23: 9 | M23: 7 | N23: 5 | O23: 9 | P23: 6 | Q23: 9 | R23: 7 | S23: 5 | T23: 9 | U23: 6 | V23: 9 | W23: 7 | X23: 5 | Y23: 9 | Z23: 6 | AA23: 9 | AB23: 7 | AC23: 5 | AD23: 9 | AE23: 6 | AF23: 9 | AG23: 7 | AH23: 5 | AI23: 9 | AJ23: 6 | AS23: =SUM(D23:AR23) -> 216
C24: Boc titoir | G24: 3 | H24: 2 | I24: 2 | J24: 2 | K24: 2 | L24: 3 | M24: 2 | N24: 2 | O24: 2 | P24: 2 | Q24: 3 | R24: 2 | S24: 2 | T24: 2 | U24: 2 | V24: 3 | W24: 2 | X24: 2 | Y24: 2 | Z24: 2 | AA24: 3 | AB24: 2 | AC24: 2 | AD24: 2 | AE24: 2 | AF24: 3 | AG24: 2 | AH24: 2 | AI24: 2 | AJ24: 2 | AS24: =SUM(D24:AR24) -> 66
C25: Tringles & Accessoires | AS25: =SUM(D25:AR25) -> 0
B26: DRESSINGS | C26: Amg Caisson+ Etageres | G26: 6 | H26: 2 | I26: 3 | J26: 3 | L26: 6 | M26: 3 | N26: 3 | O26: 3 | Q26: 6 | R26: 3 | S26: 3 | T26: 3 | V26: 6 | W26: 3 | X26: 2 | Y26: 2 | AA26: 6 | AB26: 3 | AC26: 3 | AD26: 3 | AF26: 6 | AG26: 3 | AH26: 3 | AI26: 2 | AS26: =SUM(D26:AR26) -> 86
C27: Chambranle | G27: 6 | I27: 3 | J27: 3 | L27: 6 | M27: 3 | N27: 3 | O27: 3 | Q27: 6 | R27: 3 | S27: 3 | T27: 3 | V27: 6 | W27: 3 | AA27: 6 | AB27: 3 | AC27: 3 | AD27: 3 | AF27: 6 | AG27: 3 | AH27: 3 | AS27: =SUM(D27:AR27) -> 78
C28: Boc titoir | G28: 3 | I28: 1 | J28: 2 | L28: 3 | M28: 1 | N28: 1 | O28: 2 | Q28: 3 | R28: 1 | S28: 1 | T28: 2 | V28: 3 | W28: 1 | AA28: 3 | AB28: 1 | AC28: 1 | AD28: 2 | AF28: 3 | AG28: 1 | AH28: 1 | AS28: =SUM(D28:AR28) -> 36
C29: Tringles & Accessoires | AS29: =SUM(D29:AR29) -> 0
B30: PLACARD TECHNIQUE | C30: Cadre + Panneau | AK30: 2 | AL30: 2 | AM30: 2 | AN30: 2 | AO30: 2 | AP30: 2 | AS30: =SUM(D30:AR30) -> 12
C31: Poignées et accessoires | AS31: =SUM(D31:AR31) -> 0
A32: HICHAM | B32: CUISINE | C32: Caisson bas | G32: 410 | H32: 300 | I32: 508 | J32: 570 | K32: 440 | L32: 410 | M32: 300 | N32: 508 | O32: 570 | P32: 440 | Q32: 410 | R32: 300 | S32: 508 | T32: 570 | U32: 440 | V32: 410 | W32: 300 | X32: 508 | Y32: 570 | Z32: 440 | AA32: 410 | AB32: 300 | AC32: 508 | AD32: 570 | AE32: 440 | AF32: 410 | AG32: 300 | AH32: 508 | AI32: 570 | AJ32: 440 | AS32: =SUM(D32:AR32) -> 13368
C33: Caisson haut | G33: 410 | H33: 300 | I33: 348 | J33: 570 | K33: 440 | L33: 410 | M33: 300 | N33: 348 | O33: 570 | P33: 440 | Q33: 410 | R33: 300 | S33: 348 | T33: 570 | U33: 440 | V33: 410 | W33: 300 | X33: 348 | Y33: 570 | Z33: 440 | AA33: 410 | AB33: 300 | AC33: 348 | AD33: 570 | AE33: 440 | AF33: 410 | AG33: 300 | AH33: 348 | AI33: 570 | AJ33: 440 | AS33: =SUM(D33:AR33) -> 12408
C34: Façades & faces tiroir | G34: 820 | H34: 600 | I34: 856 | J34: 1140 | K34: 880 | L34: 820 | M34: 600 | N34: 856 | O34: 1140 | P34: 880 | Q34: 820 | R34: 600 | S34: 856 | T34: 1140 | U34: 880 | V34: 820 | W34: 600 | X34: 856 | Y34: 1140 | Z34: 880 | AA34: 820 | AB34: 600 | AC34: 856 | AD34: 1140 | AE34: 880 | AF34: 820 | AG34: 600 | AH34: 856 | AI34: 1140 | AJ34: 880 | AS34: =SUM(D34:AR34) -> 25776
C35: Poignées | AS35: =SUM(D35:AR35) -> 0
A36: AYOUB | C36: PDT | AS36: =SUM(D36:AR36) -> 0
C37: Decoupe | AS37: =SUM(D37:AR37) -> 0
C38: Socle de sol | AS38: =SUM(D38:AR38) -> 0
C39: Crédence | G39: 1 | H39: 1 | J39: 1 | K39: 1 | L39: 1 | M39: 1 | O39: 1 | P39: 1 | Q39: 1 | R39: 1 | T39: 1 | U39: 1 | V39: 1 | W39: 1 | Y39: 1 | Z39: 1 | AA39: 1 | AB39: 1 | AD39: 1 | AE39: 1 | AF39: 1 | AG39: 1 | AI39: 1 | AJ39: 1 | AS39: =SUM(D39:AR39) -> 24
C40: Plinthe sur PDT | AS40: =SUM(D40:AR40) -> 0

Sheet A2
A1: PROJET: TEMARA AVENUE ETAT DE POSE
A2: =RECAP!A2 -> DU 01/02/26 AU 16/02/26
D5: A2 | AJ5: RECAP DE POSE
D6: 1ér ETAGE | H6: 2e ETAGE | L6: 3e ETAGE | P6: 4e ETAGE | T6: 5e ETAGE | X6: 6e ETAGE | AB6: COMMUNS
B7: ARTICLES | C7: DECOMPOSITION | D7: APPART 1 | E7: APPART 2 | F7: APPART 3 | G7: APPART 4 | H7: APPART 5 | I7: APPART 6 | J7: APPART 7 | K7: APPART 8 | L7: APPART 9 | M7: APPART 10 | N7: APPART 11 | O7: APPART 12 | P7: APPART 13 | Q7: APPART 14 | R7: APPART 15 | S7: APPART 16 | T7: APPART 17 | U7: APPART 18 | V7: APPART 19 | W7: APPART 20 | X7: APPART 21 | Y7: APPART 22 | Z7: APPART 23 | AA7: APPART 24 | AB7: 6éme étage | AC7: 5éme étage | AD7: 4éme étage | AE7: 3éme étage | AF7: 2éme étage | AG7: 1ér étage | AH7: MEZZ | AI7: RDC
A8: POSEUR ZOUHAIR | B8: PORTES D'ENTRÉE | C8: Cadre + Panneau | D8: 1 | F8: 1 | G8: 1 | H8: 1 | I8: 1 | J8: 1 | K8: 1 | L8: 1 | M8: 1 | N8: 1 | O8: 1 | P8: 1 | Q8: 1 | R8: 1 | S8: 1 | T8: 1 | U8: 1 | V8: 1 | W8: 1 | X8: 1 | Y8: 1 | Z8: 1 | AA8: 1 | AJ8: =SUM(D8:AI8) -> 23
C9: Chambranle + Habillage | D9: 1 | E9: 1 | F9: 1 | G9: 1 | H9: 1 | I9: 1 | J9: 1 | K9: 1 | L9: 1 | M9: 1 | N9: 1 | O9: 1 | P9: 1 | Q9: 1 | R9: 1 | S9: 1 | T9: 1 | U9: 1 | V9: 1 | W9: 1 | X9: 1 | Y9: 1 | Z9: 1 | AA9: 1 | AJ9: =SUM(D9:AI9) -> 24
C10: Imposte | D10: 1 | E10: 1 | F10: 1 | G10: 1 | H10: 1 | I10: 1 | J10: 1 | K10: 1 | L10: 1 | M10: 1 | N10: 1 | O10: 1 | P10: 1 | Q10: 1 | R10: 1 | S10: 1 | T10: 1 | U10: 1 | V10: 1 | W10: 1 | X10: 1 | Y10: 1 | Z10: 1 | AA10: 1 | AJ10: =SUM(D10:AI10) -> 24
C11: Butoirs, Judas, Poignée et serrures , Canon | D11: 1 | F11: 1 | G11: 1 | H11: 1 | I11: 1 | J11: 1 | K11: 1 | L11: 1 | M11: 1 | N11: 1 | O11: 1 | P11: 1 | Q11: 1 | R11: 1 | S11: 1 | T11: 1 | U11: 1 | V11: 1 | W11: 1 | X11: 1 | Y11: 1 | Z11: 1 | AA11: 1 | AJ11: =SUM(D11:AI11) -> 23
B12: PORTES INTÉRIEURES | C12: Cadre + Panneau | D12: 7 | E12: TEMOIN | F12: 7 | G12: 8 | H12: 7 | I12: 7 | J12: 7 | K12: 8 | L12: 7 | M12: 7 | N12: 7 | O12: 8 | P12: 7 | Q12: 7 | R12: 7 | S12: 8 | T12: 7 | U12: 7 | V12: 7 | W12: 8 | X12: 7 | Y12: 7 | Z12: 7 | AA12: 8 | AJ12: =SUM(D12:AI12) -> 167
C13: Chambranle + Habillage | D13: 7 | F13: 7 | G13: 8 | H13: 7 | I13: 7 | J13: 7 | K13: 8 | L13: 7 | M13: 7 | N13: 7 | O13: 8 | P13: 7 | Q13: 7 | R13: 7 | S13: 8 | T13: 7 | U13: 7 | V13: 7 | W13: 8 | X13: 7 | Y13: 7 | Z13: 7 | AA13: 8 | AJ13: =SUM(D13:AI13) -> 167
C14: Imposte | D14: 7 | F14: 7 | G14: 8 | H14: 7 | I14: 7 | J14: 7 | K14: 8 | L14: 7 | M14: 7 | N14: 7 | O14: 8 | P14: 7 | Q14: 7 | R14: 7 | S14: 8 | T14: 7 | U14: 7 | V14: 7 | W14: 8 | X14: 7 | Y14: 7 | Z14: 7 | AA14: 8 | AJ14: =SUM(D14:AI14) -> 167
C15: Butoirs, Poignée et serrures, Canon & Condamnation | D15: 7 | F15: 7 | G15: 8 | H15: 7 | I15: 7 | J15: 7 | K15: 8 | L15: 7 | M15: 7 | N15: 7 | O15: 8 | P15: 7 | Q15: 7 | R15: 7 | S15: 8 | T15: 7 | U15: 7 | V15: 7 | W15: 8 | X15: 7 | Y15: 7 | Z15: 7 | AA15: 8 | AJ15: =SUM(D15:AI15) -> 167
B16: PORTES ESCALIERS / SECOURS | C16: Cadre + Panneau | E16: TEMOIN | AB16: 2 | AC16: 2 | AD16: 1 | AE16: 1 | AF16: 1 | AG16: 2 | AI16: 1 | AJ16: =SUM(D16:AI16) -> 10
C17: Chambranle + Habillage | AB17: 1 | AC17: 2 | AD17: 2 | AE17: 1 | AF17: 1 | AG17: 2 | AI17: 1 | AJ17: =SUM(D17:AI17) -> 10
C18: Imposte | AB18: 2 | AC18: 2 | AD18: 1 | AE18: 1 | AF18: 1 | AG18: 2 | AI18: 1 | AJ18: =SUM(D18:AI18) -> 10
C19: Ferme porte, Poignée et serrures, Barre anti panique | AB19: 2 | AC19: 2 | AD19: 1 | AE19: 1 | AF19: 1 | AG19: 2 | AI19: 1 | AJ19: =SUM(D19:AI19) -> 10
A20: POSEUR ZEMOURI | B20: PLACARDS | C20: Amg Caisson ( quantité en ouvrants) | D20: 9 | E20: TEMOIN | F20: 10 | G20: 10 | H20: 9 | I20: 18 | J20: 10 | K20: 10 | L20: 9 | M20: 18 | N20: 10 | O20: 10 | P20: 9 | Q20: 17 | R20: 10 | S20: 10 | T20: 9 | U20: 18 | V20: 10 | W20: 10 | X20: 9 | Y20: 18 | Z20: 10 | AA20: 10 | AJ20: =SUM(D20:AI20) -> 263
C21: Etageres | D21: 9 | F21: 10 | G21: 10 | H21: 9 | I21: 18 | J21: 10 | K21: 10 | L21: 9 | M21: 18 | N21: 10 | O21: 10 | P21: 9 | Q21: 17 | R21: 10 | S21: 10 | T21: 9 | U21: 18 | V21: 10 | W21: 10 | X21: 9 | Y21: 18 | Z21: 10 | AA21: 10 | AJ21: =SUM(D21:AI21) -> 263
C22: Ouvrants | D22: 6 | F22: 10 | G22: 10 | H22: 9 | I22: 14 | J22: 10 | K22: 10 | L22: 9 | M22: 18 | N22: 10 | O22: 10 | P22: 9 | Q22: 17 | R22: 10 | S22: 10 | T22: 9 | U22: 18 | V22: 10 | W22: 10 | X22: 9 | Y22: 18 | Z22: 10 | AA22: 10 | AJ22: =SUM(D22:AI22) -> 256
C23: Chambranle | D23: 9 | F23: 10 | G23: 10 | H23: 9 | I23: 18 | J23: 10 | K23: 10 | L23: 9 | M23: 18 | N23: 10 | O23: 10 | P23: 9 | Q23: 17 | R23: 10 | S23: 10 | T23: 9 | U23: 18 | V23: 10 | W23: 10 | X23: 9 | Y23: 18 | Z23: 10 | AA23: 10 | AJ23: =SUM(D23:AI23) -> 263
C24: Boc titoir | D24: 2 | F24: 3 | G24: 2 | H24: 2 | I24: 3 | J24: 2 | K24: 2 | L24: 2 | M24: 3 | N24: 2 | O24: 2 | P24: 2 | Q24: 3 | R24: 2 | S24: 2 | T24: 2 | U24: 3 | V24: 2 | W24: 2 | X24: 2 | Y24: 2 | Z24: 2 | AA24: 2 | AJ24: =SUM(D24:AI24) -> 51
C25: Tringles & Accessoires | D25: 6 | F25: 10 | G25: 10 | H25: 9 | I25: 8 | J25: 10 | K25: 10 | L25: 9 | M25: 8 | N25: 10 | O25: 10 | P25: 9 | Q25: 8 | R25: 10 | S25: 10 | T25: 6 | U25: 2 | V25: 10 | W25: 7 | X25: 6 | Y25: 2 | Z25: 6 | AA25: 0 | AJ25: =SUM(D25:AI25) -> 176
B26: DRESSINGS | C26: Amg Caisson+ Etageres | D26: 12 | E26: TEMOIN | F26: 6 | H26: 12 | J26: 6 | L26: 8 | N26: 6 | P26: 8 | R26: 6 | T26: 8 | V26: 6 | X26: 12 | Z26: 6 | AJ26: =SUM(D26:AI26) -> 96
C27: Chambranle | AJ27: =SUM(D27:AI27) -> 0
C28: Boc titoir | AJ28: =SUM(D28:AI28) -> 0
C29: Tringles & Accessoires | AJ29: =SUM(D29:AI29) -> 0
B30: PLACARD TECHNIQUE | C30: Cadre + Panneau | E30: TEMOIN | AB30: 2 | AC30: 2 | AD30: 2 | AE30: 2 | AF30: 2 | AG30: 2 | AJ30: =SUM(D30:AI30) -> 12
C31: Poignées et accessoires | AJ31: =SUM(D31:AI31) -> 0
A32: HICHAM | B32: CUISINE | C32: Caisson bas | D32: 357 | E32: TEMOIN | F32: 312 | G32: 427 | H32: 357 | I32: 312 | J32: 312 | K32: 427 | L32: 357 | M32: 312 | N32: 312 | O32: 427 | P32: 357 | Q32: 312 | R32: 312 | S32: 427 | T32: 357 | U32: 312 | V32: 312 | W32: 427 | X32: 357 | Y32: 312 | Z32: 312 | AA32: 435 | AJ32: =SUM(D32:AI32) -> 8144
C33: Caisson haut | D33: 357 | F33: 312 | G33: 427 | H33: 357 | I33: 312 | J33: 312 | K33: 427 | L33: 357 | M33: 312 | N33: 312 | O33: 427 | P33: 357 | Q33: 312 | R33: 312 | S33: 427 | T33: 357 | U33: 312 | V33: 312 | W33: 427 | X33: 357 | Y33: 312 | Z33: 312 | AA33: 435 | AJ33: =SUM(D33:AI33) -> 8144
C34: Façades & faces tiroir | D34: 357 | F34: 624 | G34: 854 | H34: 714 | I34: 624 | J34: 624 | K34: 854 | L34: 714 | M34: 624 | N34: 624 | O34: 854 | P34: 714 | Q34: 624 | R34: 624 | S34: 854 | T34: 714 | U34: 624 | V34: 624 | W34: 854 | X34: 714 | Y34: 624 | Z34: 624 | AA34: 870 | AJ34: =SUM(D34:AI34) -> 15931
C35: Poignées | AJ35: =SUM(D35:AI35) -> 0
A36: AYOUB | C36: PDT | D36: 357 | F36: 312 | G36: 427 | H36: 357 | I36: 312 | J36: 312 | K36: 427 | L36: 357 | M36: 312 | N36: 312 | O36: 427 | P36: 357 | Q36: 312 | R36: 312 | S36: 427 | T36: 357 | U36: 312 | V36: 312 | W36: 427 | X36: 357 | Y36: 312 | Z36: 312 | AA36: 435 | AJ36: =SUM(D36:AI36) -> 8144
C37: Decoupe | D37: 1 | F37: 1 | G37: 1 | H37: 1 | I37: 1 | J37: 1 | K37: 1 | L37: 1 | M37: 1 | N37: 1 | O37: 1 | P37: 1 | Q37: 1 | R37: 1 | S37: 1 | T37: 1 | U37: 1 | V37: 1 | W37: 1 | X37: 1 | Y37: 1 | Z37: 1 | AA37: 1 | AJ37: =SUM(D37:AI37) -> 23
C38: Socle de sol | D38: 1 | F38: 1 | G38: 1 | H38: 1 | I38: 1 | J38: 1 | K38: 1 | L38: 1 | M38: 1 | N38: 1 | O38: 1 | P38: 1 | Q38: 1 | R38: 1 | S38: 1 | T38: 1 | U38: 1 | V38: 1 | W38: 1 | X38: 1 | Y38: 1 | Z38: 1 | AA38: 1 | AJ38: =SUM(D38:AI38) -> 23
C39: Crédence | D39: 1 | F39: 1 | G39: 1 | H39: 1 | I39: 1 | J39: 1 | K39: 1 | L39: 1 | M39: 1 | N39: 1 | O39: 1 | P39: 1 | Q39: 1 | R39: 1 | S39: 1 | T39: 1 | U39: 1 | V39: 1 | W39: 1 | X39: 1 | Y39: 1 | Z39: 1 | AA39: 1 | AJ39: =SUM(D39:AI39) -> 23
C40: Plinthe sur PDT | D40: 1 | F40: 1 | G40: 1 | H40: 1 | I40: 1 | J40: 1 | K40: 1 | L40: 1 | M40: 1 | N40: 1 | O40: 1 | P40: 1 | Q40: 1 | R40: 1 | S40: 1 | T40: 1 | U40: 1 | V40: 1 | W40: 1 | X40: 1 | Y40: 1 | Z40: 1 | AA40: 1 | AJ40: =SUM(D40:AI40) -> 23

Sheet A1
A1: PROJET: TEMARA AVENUE ETAT DE POSE
A2: =RECAP!A2 -> DU 01/02/26 AU 16/02/26
D5: A1 | AJ5: RECAP DE POSE
D6: 1ér ETAGE | H6: 2e ETAGE | L6: 3e ETAGE | P6: 4e ETAGE | T6: 5e ETAGE | X6: 6e ETAGE | AB6: COMMUNS
B7: ARTICLES | C7: DECOMPOSITION | D7: APPART 1 | E7: APPART 2 | F7: APPART 3 | G7: APPART 4 | H7: APPART 5 | I7: APPART 6 | J7: APPART 7 | K7: APPART 8 | L7: APPART 9 | M7: APPART 10 | N7: APPART 11 | O7: APPART 12 | P7: APPART 13 | Q7: APPART 14 | R7: APPART 15 | S7: APPART 16 | T7: APPART 17 | U7: APPART 18 | V7: APPART 19 | W7: APPART 20 | X7: APPART 21 | Y7: APPART 22 | Z7: APPART 23 | AA7: APPART 24 | AB7: 6éme étage | AC7: 5éme étage | AD7: 4éme étage | AE7: 3éme étage | AF7: 2éme étage | AG7: 1ér étage | AH7: MEZZ | AI7: RDC
A8: POSEUR ZOUHAIR | B8: PORTES D'ENTRÉE | C8: Cadre + Panneau | D8: 1 | E8: 1 | F8: 1 | G8: 1 | H8: 1 | I8: 1 | J8: 1 | K8: 1 | L8: 1 | M8: 1 | N8: 1 | O8: 1 | P8: 1 | Q8: 1 | R8: 1 | S8: 1 | T8: 1 | U8: 1 | V8: 1 | W8: 1 | X8: 1 | Y8: 1 | Z8: 1 | AA8: 1 | AJ8: =SUM(D8:AI8) -> 24
C9: Chambranle + Habillage | AJ9: =SUM(D9:AI9) -> 0
C10: Imposte | AJ10: =SUM(D10:AI10) -> 0
C11: Butoirs, Judas, Poignée et serrures , Canon | AJ11: =SUM(D11:AI11) -> 0
B12: PORTES INTÉRIEURES | C12: Cadre + Panneau | D12: 7 | E12: 5 | F12: 5 | G12: 5 | H12: 7 | I12: 5 | J12: 7 | K12: 5 | L12: 7 | M12: 4 | N12: 3 | O12: 5 | P12: 5 | Q12: 4 | R12: 3 | S12: 5 | T12: 5 | U12: 4 | V12: 3 | W12: 5 | X12: 7 | Y12: 5 | Z12: 5 | AA12: 7 | AJ12: =SUM(D12:AI12) -> 123
C13: Chambranle + Habillage | AJ13: =SUM(D13:AI13) -> 0
C14: Imposte | AJ14: =SUM(D14:AI14) -> 0
C15: Butoirs, Poignée et serrures, Canon & Condamnation | AJ15: =SUM(D15:AI15) -> 0
B16: PORTES ESCALIERS / SECOURS | C16: Cadre + Panneau | AB16: 2 | AC16: 2 | AD16: 2 | AE16: 2 | AF16: 2 | AG16: 1 | AI16: 1 | AJ16: =SUM(D16:AI16) -> 12
C17: Chambranle + Habillage | AB17: 2 | AC17: 2 | AD17: 2 | AE17: 2 | AF17: 2 | AG17: 1 | AI17: 1 | AJ17: =SUM(D17:AI17) -> 12
C18: Imposte | AB18: 2 | AC18: 2 | AD18: 2 | AE18: 2 | AF18: 2 | AG18: 1 | AI18: 1 | AJ18: =SUM(D18:AI18) -> 12
C19: Ferme porte, Poignée et serrures, Barre anti panique | AB19: 2 | AC19: 2 | AD19: 2 | AE19: 2 | AF19: 2 | AG19: 1 | AI19: 1 | AJ19: =SUM(D19:AI19) -> 12
A20: POSEUR ZEMOURI | B20: PLACARDS | C20: Amg Caisson ( quantité en ouvrants) | D20: 16 | E20: 7 | F20: 14 | G20: 12 | H20: 15 | I20: 7 | J20: 15 | K20: 12 | L20: 15 | M20: 7 | N20: 13 | O20: 11 | P20: 15 | Q20: 7 | R20: 14 | S20: 11 | T20: 15 | U20: 7 | V20: 15 | W20: 12 | X20: 16 | Y20: 7 | Z20: 14 | AA20: 12 | AJ20: =SUM(D20:AI20) -> 289
C21: Etageres | D21: 16 | E21: 7 | F21: 14 | G21: 12 | H21: 15 | I21: 7 | J21: 15 | K21: 12 | L21: 15 | M21: 7 | N21: 13 | O21: 11 | P21: 15 | Q21: 7 | R21: 14 | S21: 11 | T21: 15 | U21: 7 | V21: 15 | W21: 12 | X21: 16 | Y21: 7 | Z21: 14 | AA21: 12 | AJ21: =SUM(D21:AI21) -> 289
C22: Ouvrants | D22: 16 | E22: 7 | F22: 14 | G22: 12 | H22: 12 | I22: 7 | J22: 15 | K22: 12 | L22: 15 | M22: 7 | N22: 13 | O22: 11 | P22: 15 | Q22: 7 | R22: 14 | S22: 11 | T22: 15 | U22: 7 | V22: 15 | W22: 12 | X22: 16 | Y22: 7 | Z22: 14 | AA22: 12 | AJ22: =SUM(D22:AI22) -> 286
C23: Chambranle | AJ23: =SUM(D23:AI23) -> 0
C24: Boc titoir | AJ24: =SUM(D24:AI24) -> 0
C25: Tringles & Accessoires | AJ25: =SUM(D25:AI25) -> 0
B26: DRESSINGS | C26: Amg Caisson+ Etageres | E26: 5 | I26: 5 | M26: 5 | Q26: 5 | U26: 5 | Y26: 5 | AJ26: =SUM(D26:AI26) -> 30
C27: Chambranle | E27: 5 | I27: 5 | M27: 5 | Q27: 5 | U27: 5 | Y27: 5 | AJ27: =SUM(D27:AI27) -> 30
C28: Boc titoir | AJ28: =SUM(D28:AI28) -> 0
C29: Tringles & Accessoires | AJ29: =SUM(D29:AI29) -> 0
B30: PLACARD TECHNIQUE | C30: Cadre + Panneau | AJ30: =SUM(D30:AI30) -> 0
C31: Poignées et accessoires | AJ31: =SUM(D31:AI31) -> 0
A32: HICHAM | B32: CUISINE | C32: Caisson bas | D32: 330 | E32: 230 | F32: 230 | G32: 330 | H32: 330 | I32: 230 | J32: 230 | K32: 330 | L32: 330 | M32: 230 | N32: 230 | O32: 330 | P32: 330 | Q32: 230 | R32: 230 | S32: 330 | T32: 330 | U32: 230 | V32: 230 | W32: 330 | X32: 330 | Y32: 230 | Z32: 230 | AA32: 330 | AJ32: =SUM(D32:AI32) -> 6720
C33: Caisson haut | D33: 330 | E33: 230 | F33: 230 | G33: 330 | H33: 330 | I33: 230 | J33: 230 | K33: 330 | L33: 330 | M33: 230 | N33: 230 | O33: 330 | P33: 330 | Q33: 230 | R33: 230 | S33: 330 | T33: 330 | U33: 230 | V33: 230 | W33: 330 | X33: 330 | Y33: 230 | Z33: 230 | AA33: 330 | AJ33: =SUM(D33:AI33) -> 6720
C34: Façades & faces tiroir | AJ34: =SUM(D34:AI34) -> 0
C35: Poignées | AJ35: =SUM(D35:AI35) -> 0
A36: AYOUB | C36: PDT | AJ36: =SUM(D36:AI36) -> 0
C37: Decoupe | AJ37: =SUM(D37:AI37) -> 0
C38: Socle de sol | AJ38: =SUM(D38:AI38) -> 0
C39: Crédence | AJ39: =SUM(D39:AI39) -> 0
C40: Plinthe sur PDT | AJ40: =SUM(D40:AI40) -> 0
A41: POSEUR MOURAD | B41: PORTES D'ENTRÉE | C41: Cadre + Panneau | AJ41: =SUM(D41:AI41) -> 0
C42: Chambranle + Habillage | AJ42: =SUM(D42:AI42) -> 0
...

Sheet RECAP
A1: PROJET: TEMARA AVENUE ETAT DE POSE
A2: DU 01/02/26 AU 16/02/26
B5: ARTICLES | C5: DECOMPOSITION | D5: DECOMPOSITION PRIX % | E5: RECAP A1 | F5: RECAP A2 | G5: RECAP A3 | H5: RECAP A4 | I5: RECAP A5 | J5: ARZANA | K5: RECAP DE POSE | L5: PRIX | M5: MONTANT | O5: QUANTITÉ MARCHÉ
A6: POSEUR ZOUHAIR | B6: PORTES D'ENTRÉE | C6: Cadre + Panneau | D6: 0.5 | E6: =+'A1'!AJ8 -> 24 | F6: =+'A2'!AJ8 -> 23 | G6: 0 | H6: =+'A4'!AF8 -> 0 | I6: =+'A5'!AJ8 -> 0 | J6: =+'A5'!AK8 -> 0 | K6: =SUM(E6:J6) -> 47 | L6: 150 | M6: =+L$6*K6*D6 -> 3525 | O6: 125 | X6: =+'A3'!BI8 -> 0 | Z6: =+'A1'!BD8 -> 0 | AA6: =+'A2'!BD8 -> 0 | AC6: =+'A4'!AZ8 -> 0 | AD6: =+'A5'!BD8 -> 0
C7: Chambranle + Habillage | D7: 0.2 | E7: =+'A1'!AJ9 -> 0 | F7: =+'A2'!AJ9 -> 24 | G7: 0 | H7: =+'A4'!AF9 -> 0 | I7: =+'A5'!AJ9 -> 0 | J7: =+'A5'!AK9 -> 0 | K7: =SUM(E7:J7) -> 24 | M7: =+L$6*K7*D7 -> 720 | X7: =+'A3'!BI9 -> 0 | Z7: =+'A1'!BD9 -> 0 | AA7: =+'A2'!BD9 -> 0 | AC7: =+'A4'!AZ9 -> 0 | AD7: =+'A5'!BD9 -> 0
C8: Imposte | D8: 0.15 | E8: =+'A1'!AJ10 -> 0 | F8: =+'A2'!AJ10 -> 24 | G8: 0 | H8: =+'A4'!AF10 -> 0 | I8: =+'A5'!AJ10 -> 0 | J8: =+'A5'!AK10 -> 0 | K8: =SUM(E8:J8) -> 24 | M8: =+L$6*K8*D8 -> 540 | R8: =+A6 -> POSEUR ZOUHAIR | X8: =+'A3'!BI10 -> 0 | Z8: =+'A1'!BD10 -> 0 | AA8: =+'A2'!BD10 -> 0 | AC8: =+'A4'!AZ10 -> 0 | AD8: =+'A5'!BD10 -> 0
C9: Butoirs, Judas, Poignée et serrures , Canon | D9: 0.15 | E9: =+'A1'!AJ11 -> 0 | F9: =+'A2'!AJ11 -> 23 | G9: 0 | H9: =+'A4'!AF11 -> 0 | I9: =+'A5'!AJ11 -> 0 | J9: =+'A5'!AK11 -> 0 | K9: =SUM(E9:J9) -> 23 | M9: =+L$6*K9*D9 -> 517.5 | R9: TOTAL AVANCE | S9: =9000+3000+5000+4000+5000+2000 -> 28000 | X9: =+'A3'!BI11 -> 0 | Z9: =+'A1'!BD11 -> 0 | AA9: =+'A2'!BD11 -> 0 | AC9: =+'A4'!AZ11 -> 0 | AD9: =+'A5'!BD11 -> 0
B10: PORTES INTÉRIEURES | C10: Cadre + Panneau | D10: 0.5 | E10: =+'A1'!AJ12 -> 123 | F10: =+'A2'!AJ12 -> 167 | G10: 0 | H10: =+'A4'!AF12 -> 11 | I10: =+'A5'!AJ12 -> 0 | J10: 9 | K10: =SUM(E10:J10) -> 310 | L10: 120 | M10: =+L$10*K10*D10 -> 18600 | O10: 789 | R10: TOTAL POSE | S10: =SUM(M6:M17)-((D10*E10*L10)+(D11*E11*L10)+(D12*E12*L10)+(D13*E13*L10)+(D6*E6*L6)+(D7*E7*L6)+(D8*E8*L6)+(D9*E9*L6)) -> 32944.5 | T10: RF | U10: =+S10*10% -> 3294.45 | X10: =+'A3'!BI12 -> 0 | Z10: =+'A1'!BD12 -> 0 | AA10: =+'A2'!BD12 -> 0 | AC10: =+'A4'!AZ12 -> 0 | AD10: =+'A5'!BD12 -> 0
C11: Chambranle + Habillage | D11: 0.2 | E11: =+'A1'!AJ13 -> 0 | F11: =+'A2'!AJ13 -> 167 | G11: 0 | H11: =+'A4'!AF13 -> 0 | I11: =+'A5'!AJ13 -> 0 | J11: =+'A5'!AK13 -> 0 | K11: =SUM(E11:J11) -> 167 | M11: =+L$10*K11*D11 -> 4008 | T11: Reste dû au poseur | U11: =S12-U10 -> 1650.05 | X11: =+'A3'!BI13 -> 0 | Z11: =+'A1'!BD13 -> 0 | AA11: =+'A2'!BD13 -> 0 | AC11: =+'A4'!AZ13 -> 0 | AD11: =+'A5'!BD13 -> 0
C12: Imposte | D12: 0.15 | E12: =+'A1'!AJ14 -> 0 | F12: =+'A2'!AJ14 -> 167 | G12: 0 | H12: =+'A4'!AF14 -> 0 | I12: =+'A5'!AJ14 -> 0 | J12: 9 | K12: =SUM(E12:J12) -> 176 | M12: =+L$10*K12*D12 -> 3168 | R12: RESTE | S12: =+S10-S9 -> 4944.5 | X12: =+'A3'!BI14 -> 0 | Z12: =+'A1'!BD14 -> 0 | AA12: =+'A2'!BD14 -> 0 | AC12: =+'A4'!AZ14 -> 0 | AD12: =+'A5'!BD14 -> 0
C13: Butoirs, Poignée et serrures, Canon & Condamnation | D13: 0.15 | E13: =+'A1'!AJ15 -> 0 | F13: =+'A2'!AJ15 -> 167 | G13: 0 | H13: =+'A4'!AF15 -> 0 | I13: =+'A5'!AJ15 -> 0 | J13: =+'A5'!AK15 -> 0 | K13: =SUM(E13:J13) -> 167 | M13: =+L$10*K13*D13 -> 3006 | X13: =+'A3'!BI15 -> 0 | Z13: =+'A1'!BD15 -> 0 | AA13: =+'A2'!BD15 -> 0 | AC13: =+'A4'!AZ15 -> 0 | AD13: =+'A5'!BD15 -> 0
B14: PORTES ESCALIERS / SECOURS | C14: Cadre + Panneau | D14: 0.5 | E14: =+'A1'!AJ16 -> 12 | F14: =+'A2'!AJ16 -> 10 | G14: ='A3'!AS16 -> 12 | H14: =+'A4'!AF16 -> 13 | I14: =+'A5'!AJ16 -> 9 | J14: =+'A5'!AK16 -> 0 | K14: =SUM(E14:J14) -> 56 | L14: 150 | M14: =+L$14*K14*D14 -> 4200 | O14: 115 | X14: =+'A3'!BI16 -> 0 | Z14: =+'A1'!BD16 -> 0 | AA14: =+'A2'!BD16 -> 0 | AC14: =+'A4'!AZ16 -> 0 | AD14: =+'A5'!BD16 -> 0
C15: Chambranle + Habillage | D15: 0.2 | E15: =+'A1'!AJ17 -> 12 | F15: =+'A2'!AJ17 -> 10 | G15: ='A3'!AS17 -> 0 | H15: =+'A4'!AF17 -> 13 | I15: =+'A5'!AJ17 -> 9 | J15: =+'A5'!AK17 -> 0 | K15: =SUM(E15:J15) -> 44 | M15: =+L$14*K15*D15 -> 1320 | X15: =+'A3'!BI17 -> 0 | Z15: =+'A1'!BD17 -> 0 | AA15: =+'A2'!BD17 -> 0 | AC15: =+'A4'!AZ17 -> 0 | AD15: =+'A5'!BD17 -> 0
C16: Imposte | D16: 0.15 | E16: =+'A1'!AJ18 -> 12 | F16: =+'A2'!AJ18 -> 10 | G16: ='A3'!AS18 -> 12 | H16: =+'A4'!AF18 -> 13 | I16: =+'A5'!AJ18 -> 9 | J16: =+'A5'!AK18 -> 0 | K16: =SUM(E16:J16) -> 56 | M16: =+L$14*K16*D16 -> 1260 | X16: =+'A3'!BI18 -> 0 | Z16: =+'A1'!BD18 -> 0 | AA16: =+'A2'!BD18 -> 0 | AC16: =+'A4'!AZ18 -> 0 | AD16: =+'A5'!BD18 -> 0
C17: Ferme porte, Poignée et serrures, Barre anti panique | D17: 0.15 | E17: =+'A1'!AJ19 -> 12 | F17: =+'A2'!AJ19 -> 10 | G17: ='A3'!AS19 -> 12 | H17: =+'A4'!AF19 -> 13 | I17: =+'A5'!AJ19 -> 9 | J17: =+'A5'!AK19 -> 0 | K17: =SUM(E17:J17) -> 56 | M17: =+L$14*K17*D17 -> 1260 | X17: =+'A3'!BI19 -> 0 | Z17: =+'A1'!BD19 -> 0 | AA17: =+'A2'!BD19 -> 0 | AC17: =+'A4'!AZ19 -> 0 | AD17: =+'A5'!BD19 -> 0
A18: POSEUR ZEMOURI | B18: PLACARDS | C18: Amg Caisson ( quantité en ouvrants) | D18: 0.4 | E18: =+'A1'!AJ20 -> 289 | F18: =+'A2'!AJ20 -> 263 | G18: 0 | H18: =+'A4'!AF20 -> 0 | I18: =+'A5'!AJ20 -> 0 | J18: 0 | K18: =SUM(E18:J18) -> 552 | L18: 60 | M18: =+L$18*K18*D18 -> 13248 | O18: 401 | X18: =+'A3'!BI20 -> 0 | Z18: =+'A1'!BD20 -> 0 | AA18: =+'A2'!BD20 -> 0 | AC18: =+'A4'!AZ20 -> 0 | AD18: =+'A5'!BD20 -> 0
C19: Etageres | D19: 0.1 | E19: =+'A1'!AJ21 -> 289 | F19: =+'A2'!AJ21 -> 263 | G19: 0 | H19: =+'A4'!AF21 -> 0 | I19: =+'A5'!AJ21 -> 0 | J19: 0 | K19: =SUM(E19:J19) -> 552 | M19: =+L$18*K19*D19 -> 3312 | R19: =+A18 -> POSEUR ZEMOURI | X19: =+'A3'!BI21 -> 0 | Z19: =+'A1'!BD21 -> 0 | AA19: =+'A2'!BD21 -> 0 | AC19: =+'A4'!AZ21 -> 0 | AD19: =+'A5'!BD21 -> 0
C20: Ouvrants | D20: 0.2 | E20: =+'A1'!AJ22 -> 286 | F20: =+'A2'!AJ22 -> 256 | G20: 0 | H20: =+'A4'!AF22 -> 0 | I20: =+'A5'!AJ22 -> 0 | J20: 0 | K20: =SUM(E20:J20) -> 542 | M20: =+L$18*K20*D20 -> 6504 | R20: TOTAL AVANCE | S20: =1500+3000+5000+4000+6000+5000+7000+2000+2000 -> 35500 | X20: =+'A3'!BI22 -> 0 | Z20: =+'A1'!BD22 -> 0 | AA20: =+'A2'!BD22 -> 0 | AC20: =+'A4'!AZ22 -> 0 | AD20: =+'A5'!BD22 -> 0
C21: Chambranle | D21: 0.1 | E21: =+'A1'!AJ23 -> 0 | F21: =+'A2'!AJ23 -> 263 | G21: 0 | H21: =+'A4'!AF23 -> 0 | I21: =+'A5'!AJ23 -> 0 | J21: 0 | K21: =SUM(E21:J21) -> 263 | M21: =+L$18*K21*D21 -> 1578 | R21: TOTAL POSE | S21: =SUM(M18:M27)+((D10*E10*L10)+(D11*E11*L10)+(D12*E12*L10)+(D13*E13*L10)+(D6*E6*L6)+(D7*E7*L6)+(D8*E8*L6)+(D9*E9*L6)) -> 51744 | T21: RF | U21: =+S21*10% -> 5174.4 | X21: =+'A3'!BI23 -> 0 | Z21: =+'A1'!BD23 -> 0 | AA21: =+'A2'!BD23 -> 0 | AC21: =+'A4'!AZ23 -> 0 | AD21: =+'A5'!BD23 -> 0
C22: Boc titoir | D22: 0.1 | E22: =+'A1'!AJ24 -> 0 | F22: =+'A2'!AJ24 -> 51 | G22: 0 | H22: =+'A4'!AF24 -> 0 | I22: =+'A5'!AJ24 -> 0 | J22: 0 | K22: =SUM(E22:J22) -> 51 | M22: =+L$18*K22*D22 -> 306 | T22: Reste dû au poseur | U22: =S23-U21 -> 11069.6 | X22: =+'A3'!BI24 -> 0 | Z22: =+'A1'!BD24 -> 0 | AA22: =+'A2'!BD24 -> 0 | AC22: =+'A4'!AZ24 -> 0 | AD22: =+'A5'!BD24 -> 0
C23: Tringles & Accessoires | D23: 0.1 | E23: =+'A1'!AJ25 -> 0 | F23: =+'A2'!AJ25 -> 176 | G23: 0 | H23: =+'A4'!AF25 -> 0 | I23: =+'A5'!AJ25 -> 0 | J23: =+'A5'!AK25 -> 0 | K23: =SUM(E23:J23) -> 176 | M23: =+L$18*K23*D23 -> 1056 | R23: RESTE | S23: =+S21-S20 -> 16244 | X23: =+'A3'!BI25 -> 0 | Z23: =+'A1'!BD25 -> 0 | AA23: =+'A2'!BD25 -> 0 | AC23: =+'A4'!AZ25 -> 0 | AD23: =+'A5'!BD25 -> 0
B24: DRESSINGS | C24: Amg Caisson+ Etageres | D24: 0.5 | E24: =+'A1'!AJ26*4 -> 120 | F24: =+'A2'!AJ26*4 -> 384 | G24: 0 | H24: =+'A4'!AF26 -> 0 | I24: =+'A5'!AJ26 -> 0 | J24: =+'A5'!AK26 -> 0 | K24: =SUM(E24:J24) -> 504 | L24: 60 | M24: =+L$24*K24*D24 -> 15120 | O24: 68 | X24: =+'A3'!BI26 -> 0 | Z24: =+'A1'!BD26 -> 0 | AA24: =+'A2'!BD26 -> 0 | AC24: =+'A4'!AZ26 -> 0 | AD24: =+'A5'!BD26 -> 0
C25: Chambranle | D25: 0.2 | E25: =+'A1'!AJ27*4 -> 120 | F25: =+'A2'!AJ27 -> 0 | G25: 0 | H25: =+'A4'!AF27 -> 0 | I25: =+'A5'!AJ27 -> 0 | J25: =+'A5'!AK27 -> 0 | K25: =SUM(E25:J25) -> 120 | M25: =+L$24*K25*D25 -> 1440 | X25: =+'A3'!BI27 -> 0 | Z25: =+'A1'!BD27 -> 0 | AA25: =+'A2'!BD27 -> 0 | AC25: =+'A4'!AZ27 -> 0 | AD25: =+'A5'!BD27 -> 0
C26: Boc titoir | D26: 0.1 | E26: =+'A1'!AJ28 -> 0 | F26: =+'A2'!AJ28 -> 0 | G26: 0 | H26: =+'A4'!AF28 -> 0 | I26: =+'A5'!AJ28 -> 0 | J26: =+'A5'!AK28 -> 0 | K26: =SUM(E26:J26) -> 0 | M26: =+L$24*K26*D26 -> 0 | X26: =+'A3'!BI28 -> 0 | Z26: =+'A1'!BD28 -> 0 | AA26: =+'A2'!BD28 -> 0 | AC26: =+'A4'!AZ28 -> 0 | AD26: =+'A5'!BD28 -> 0
C27: Tringles & Accessoires | D27: 0.1 | E27: =+'A1'!AJ29 -> 0 | F27: =+'A2'!AJ29 -> 0 | G27: 0 | H27: =+'A4'!AF29 -> 0 | I27: =+'A5'!AJ29 -> 0 | J27: =+'A5'!AK29 -> 0 | K27: =SUM(E27:J27) -> 0 | M27: =+L$24*K27*D27 -> 0 | X27: =+'A3'!BI29 -> 0 | Z27: =+'A1'!BD29 -> 0 | AA27: =+'A2'!BD29 -> 0 | AC27: =+'A4'!AZ29 -> 0 | AD27: =+'A5'!BD29 -> 0
B28: PLACARD TECHNIQUE | C28: Cadre + Panneau | D28: 0.9 | E28: =+'A1'!AJ30 -> 0 | F28: =+'A2'!AJ30 -> 12 | G28: 0 | H28: =+'A4'!AF30 -> 12 | I28: =+'A5'!AJ30 -> 12 | J28: 18 | K28: =SUM(E28:J28) -> 54 | L28: 40 | M28: =+L$28*K28*D28 -> 1944 | O28: 70 | X28: =+'A3'!BI30 -> 0 | Z28: =+'A1'!BD30 -> 0 | AA28: =+'A2'!BD30 -> 0 | AC28: =+'A4'!AZ30 -> 0 | AD28: =+'A5'!BD30 -> 0
C29: Poignées et accessoires | D29: 0.1 | E29: =+'A1'!AJ31 -> 0 | F29: =+'A2'!AJ31 -> 0 | G29: 0 | H29: =+'A4'!AF31 -> 0 | I29: =+'A5'!AJ31 -> 0 | J29: =+'A5'!AK31 -> 0 | K29: =SUM(E29:J29) -> 0 | M29: =+L$28*K29*D29 -> 0 | X29: =+'A3'!BI31 -> 0 | Z29: =+'A1'!BD31 -> 0 | AA29: =+'A2'!BD31 -> 0 | AC29: =+'A4'!AZ31 -> 0 | AD29: =+'A5'!BD31 -> 0
A30: HICHAM | B30: CUISINE | C30: Caisson bas | D30: 0.3 | E30: =+'A1'!AJ32 -> 6720 | F30: =+'A2'!AJ32 -> 8144 | G30: 0 | H30: =+'A4'!AF32 -> 4082 | I30: =+'A5'!AJ32 -> 5955 | J30: =+'A5'!AK32 -> 0 | K30: =SUM(E30:J30) -> 24901 | M30: =+L$30*K30*D30 -> 0 | O30: 124 | X30: =+'A3'!BI32 -> 0 | Z30: =+'A1'!BD32 -> 0 | AA30: =+'A2'!BD32 -> 0 | AC30: =+'A4'!AZ32 -> 0 | AD30: =+'A5'!BD32 -> 0
C31: Caisson haut | D31: 0.3 | E31: =+'A1'!AJ33 -> 6720 | F31: =+'A2'!AJ33 -> 8144 | G31: 0 | H31: =+'A4'!AF33 -> 4082 | I31: =+'A5'!AJ33 -> 5955 | J31: =+'A5'!AK33 -> 0 | K31: =SUM(E31:J31) -> 24901 | M31: =+L$30*K31*D31 -> 0 | X31: =+'A3'!BI33 -> 0 | Z31: =+'A1'!BD33 -> 0 | AA31: =+'A2'!BD33 -> 0 | AC31: =+'A4'!AZ33 -> 0 | AD31: =+'A5'!BD33 -> 0
C32: Façades & faces tiroir | D32: 0.3 | E32: =+'A1'!AJ34 -> 0 | F32: =+'A2'!AJ34 -> 15931 | G32: 0 | H32: =+'A4'!AF34 -> 8164 | I32: =+'A5'!AJ34 -> 11910 | J32: =+'A5'!AK34 -> 0 | K32: =SUM(E32:J32) -> 36005 | M32: =+L$30*K32*D32 -> 0 | X32: =+'A3'!BI34 -> 0 | Z32: =+'A1'!BD34 -> 0 | AA32: =+'A2'!BD34 -> 0 | AC32: =+'A4'!AZ34 -> 0 | AD32: =+'A5'!BD34 -> 0
C33: Poignées | D33: 0.1 | E33: =+'A1'!AJ35 -> 0 | F33: =+'A2'!AJ35 -> 0 | G33: 0 | H33: =+'A4'!AF35 -> 0 | I33: =+'A5'!AJ35 -> 0 | J33: =+'A5'!AK35 -> 0 | K33: =SUM(E33:J33) -> 0 | M33: =+L$30*K33*D33 -> 0 | X33: =+'A3'!BI35 -> 0 | Z33: =+'A1'!BD35 -> 0 | AA33: =+'A2'!BD35 -> 0 | AC33: =+'A4'!AZ35 -> 0 | AD33: =+'A5'!BD35 -> 0
A34: AYOUB | C34: PDT | D34: 0.6 | E34: ='A1'!AJ36 -> 0 | F34: ='A2'!AJ36 -> 8144 | G34: 0 | H34: =+'A4'!AF36 -> 4082 | I34: =+'A5'!AJ36 -> 225 | J34: =+'A5'!AK36 -> 0 | K34: =SUM(E34:J34) -> 12451 | M34: =+L$34*K34*D34 -> 0 | O34: 124 | X34: =+'A3'!BI36 -> 0 | Z34: =+'A1'!BD36 -> 0 | AA34: =+'A2'!BD36 -> 0 | AC34: =+'A4'!AZ36 -> 0 | AD34: =+'A5'!BD36 -> 0
C35: Decoupe | D35: 0.1 | E35: ='A1'!AJ37 -> 0 | F35: ='A2'!AJ37 -> 23 | G35: 0 | H35: =+'A4'!AF37 -> 0 | I35: =+'A5'!AJ37 -> 1 | J35: =+'A5'!AK37 -> 0 | K35: =SUM(E35:J35) -> 24 | M35: =+L$34*K35*D35 -> 0 | X35: =+'A3'!BI37 -> 0 | Z35: =+'A1'!BD37 -> 0 | AA35: =+'A2'!BD37 -> 0 | AC35: =+'A4'!AZ37 -> 0 | AD35: =+'A5'!BD37 -> 0
C36: Socle de sol | D36: 0.1 | E36: ='A1'!AJ38 -> 0 | F36: ='A2'!AJ38 -> 23 | G36: 0 | H36: =+'A4'!AF38 -> 5 | I36: =+'A5'!AJ38 -> 1 | J36: =+'A5'!AK38 -> 0 | K36: =SUM(E36:J36) -> 29 | M36: =+L$34*K36*D36 -> 0 | X36: =+'A3'!BI38 -> 0 | Z36: =+'A1'!BD38 -> 0 | AA36: =+'A2'!BD38 -> 0 | AC36: =+'A4'!AZ38 -> 0 | AD36: =+'A5'!BD38 -> 0
C37: Crédence | D37: 0.1 | E37: ='A1'!AJ39 -> 0 | F37: ='A2'!AJ39 -> 23 | G37: 0 | H37: =+'A4'!AF39 -> 17 | I37: =+'A5'!AJ39 -> 1 | J37: =+'A5'!AK39 -> 0 | K37: =SUM(E37:J37) -> 41 | M37: =+L$34*K37*D37 -> 0 | X37: =+'A3'!BI39 -> 0 | Z37: =+'A1'!BD39 -> 0 | AA37: =+'A2'!BD39 -> 0 | AC37: =+'A4'!AZ39 -> 0 | AD37: =+'A5'!BD39 -> 0
C38: Plinthe sur PDT | D38: 0.1 | E38: ='A1'!AJ40 -> 0 | F38: ='A2'!AJ40 -> 23 | G38: 0 | H38: =+'A4'!AF40 -> 0 | I38: =+'A5'!AJ40 -> 23 | J38: =+'A5'!AK40 -> 0 | K38: =SUM(E38:J38) -> 46 | M38: =+L$34*K38*D38 -> 0 | X38: =+'A3'!BI40 -> 0 | Z38: =+'A1'!BD40 -> 0 | AA38: =+'A2'!BD40 -> 0 | AC38: =+'A4'!AZ40 -> 0 | AD38: =+'A5'!BD40 -> 0
A39: MOURAD | B39: PORTES INTÉRIEURES | C39: Cadre + Panneau | D39: 0.5 | E39: =+'A1'!AJ45 -> 32 | K39: =SUM(E39:J39) -> 32 | L39: 120 | M39: =+L$39*K39*D39 -> 1920 | O39: 125 | X39: =+'A3'!BI41 -> 0 | Z39: =+'A1'!BD53 -> 0 | AA39: =+'A2'!BD41 -> 0 | AC39: =+'A4'!AZ41 -> 0 | AD39: =+'A5'!BD41 -> 0
C40: Chambranle + Habillage | D40: 0.2 | E40: =+'A1'!AJ46 -> 17 | K40: =SUM(E40:J40) -> 17 | M40: =+L$39*K40*D40 -> 408 | X40: =+'A3'!BI42 -> 0 | Z40: =+'A1'!BD54 -> 0 | AA40: =+'A2'!BD42 -> 0 | AC40: =+'A4'!AZ42 -> 0 | AD40: =+'A5'!BD42 -> 0
C41: Imposte | D41: 0.15 | E41: =+'A1'!AJ47 -> 17 | K41: =SUM(E41:J41) -> 17 | M41: =+L$39*K41*D41 -> 306 | R41: =+A39 -> MOURAD | X41: =+'A3'!BI43 -> 0 | Z41: =+'A1'!BD55 -> 0 | AA41: =+'A2'!BD43 -> 0 | AC41: =+'A4'!AZ43 -> 0 | AD41: =+'A5'!BD43 -> 0
C42: Butoirs, Judas, Poignée et serrures , Canon | D42: 0.15 | E42: =+'A1'!AJ48 -> 13 | K42: =SUM(E42:J42) -> 13 | M42: =+L$39*K42*D42 -> 234 | R42: TOTAL AVANCE | S42: 0 | X42: =+'A3'!BI44 -> 0 | Z42: =+'A1'!BD56 -> 0 | AA42: =+'A2'!BD44 -> 0 | AC42: =+'A4'!AZ44 -> 0 | AD42: =+'A5'!BD44 -> 0
...

Sheet Feuil1
